<?xml version="1.0" ?>
<robot name="robit" xmlns:xacro="http://www.ros.org/wiki/xacro">

<xacro:include filename="$(find robit_description)/urdf/materials.xacro" />
<xacro:include filename="$(find robit_description)/urdf/robit.trans" />
<xacro:include filename="$(find robit_description)/urdf/robit.gazebo" />
<link name="base_link">
  <inertial>
    <origin xyz="-0.24756919920884493 -0.19280000000000005 0.10020673393463417" rpy="0 0 0"/>
    <mass value="400.5532480230806"/>
    <inertia ixx="6.723167" iyy="16.901386" izz="21.012505" ixy="0.0" iyz="0.0" ixz="-0.002498"/>
  </inertial>
  <visual>
    <origin xyz="0 0 0" rpy="0 0 0"/>
    <geometry>
      <mesh filename="package://robit_description/meshes/base_link.stl" scale="0.001 0.001 0.001"/>
    </geometry>
    <material name="silver"/>
  </visual>
  <collision>
    <origin xyz="0 0 0" rpy="0 0 0"/>
    <geometry>
      <mesh filename="package://robit_description/meshes/base_link.stl" scale="0.001 0.001 0.001"/>
    </geometry>
  </collision>
</link>

<link name="flipper_v1__3__1">
  <inertial>
    <origin xyz="-0.12120891726297243 0.02001249999999982 -4.999999999311111e-07" rpy="0 0 0"/>
    <mass value="27.37463049164619"/>
    <inertia ixx="0.083875" iyy="0.553977" izz="0.477411" ixy="0.0" iyz="0.0" ixz="0.0"/>
  </inertial>
  <visual>
    <origin xyz="-0.0 0.0 -0.112381" rpy="0 0 0"/>
    <geometry>
      <mesh filename="package://robit_description/meshes/flipper_v1__3__1.stl" scale="0.001 0.001 0.001"/>
    </geometry>
    <material name="silver"/>
  </visual>
  <collision>
    <origin xyz="-0.0 0.0 -0.112381" rpy="0 0 0"/>
    <geometry>
      <mesh filename="package://robit_description/meshes/flipper_v1__3__1.stl" scale="0.001 0.001 0.001"/>
    </geometry>
  </collision>
</link>

<link name="flipper_v1_1">
  <inertial>
    <origin xyz="-0.12120891726297243 -0.02001249999999999 4.999999999866223e-07" rpy="0 0 0"/>
    <mass value="27.37463049164619"/>
    <inertia ixx="0.083875" iyy="0.553977" izz="0.477411" ixy="0.0" iyz="0.0" ixz="0.0"/>
  </inertial>
  <visual>
    <origin xyz="-0.0 0.3856 -0.11238" rpy="0 0 0"/>
    <geometry>
      <mesh filename="package://robit_description/meshes/flipper_v1_1.stl" scale="0.001 0.001 0.001"/>
    </geometry>
    <material name="silver"/>
  </visual>
  <collision>
    <origin xyz="-0.0 0.3856 -0.11238" rpy="0 0 0"/>
    <geometry>
      <mesh filename="package://robit_description/meshes/flipper_v1_1.stl" scale="0.001 0.001 0.001"/>
    </geometry>
  </collision>
</link>

<link name="flipper_v1__2__1">
  <inertial>
    <origin xyz="-0.1212089172629724 0.020012499999999978 -4.999999999172333e-07" rpy="0 0 0"/>
    <mass value="27.37463049164619"/>
    <inertia ixx="0.083875" iyy="0.553977" izz="0.477411" ixy="0.0" iyz="0.0" ixz="0.0"/>
  </inertial>
  <visual>
    <origin xyz="0.4953 0.0 -0.112381" rpy="0 0 0"/>
    <geometry>
      <mesh filename="package://robit_description/meshes/flipper_v1__2__1.stl" scale="0.001 0.001 0.001"/>
    </geometry>
    <material name="silver"/>
  </visual>
  <collision>
    <origin xyz="0.4953 0.0 -0.112381" rpy="0 0 0"/>
    <geometry>
      <mesh filename="package://robit_description/meshes/flipper_v1__2__1.stl" scale="0.001 0.001 0.001"/>
    </geometry>
  </collision>
</link>

<link name="flipper_v1__1__1">
  <inertial>
    <origin xyz="-0.1212089172629724 -0.02001249999999999 4.999999999866223e-07" rpy="0 0 0"/>
    <mass value="27.37463049164619"/>
    <inertia ixx="0.083875" iyy="0.553977" izz="0.477411" ixy="-0.0" iyz="0.0" ixz="0.0"/>
  </inertial>
  <visual>
    <origin xyz="0.4953 0.3856 -0.11238" rpy="0 0 0"/>
    <geometry>
      <mesh filename="package://robit_description/meshes/flipper_v1__1__1.stl" scale="0.001 0.001 0.001"/>
    </geometry>
    <material name="silver"/>
  </visual>
  <collision>
    <origin xyz="0.4953 0.3856 -0.11238" rpy="0 0 0"/>
    <geometry>
      <mesh filename="package://robit_description/meshes/flipper_v1__1__1.stl" scale="0.001 0.001 0.001"/>
    </geometry>
  </collision>
</link>

<link name="link_0_v1_1">
  <inertial>
    <origin xyz="-2.6020852139652106e-17 -1.1102230246251565e-16 0.06578846025001595" rpy="0 0 0"/>
    <mass value="3.0117344703981304"/>
    <inertia ixx="0.005075" iyy="0.005075" izz="0.001459" ixy="0.0" iyz="0.0" ixz="0.0"/>
  </inertial>
  <visual>
    <origin xyz="0.012 0.1928 -0.18038" rpy="0 0 0"/>
    <geometry>
      <mesh filename="package://robit_description/meshes/link_0_v1_1.stl" scale="0.001 0.001 0.001"/>
    </geometry>
    <material name="silver"/>
  </visual>
  <collision>
    <origin xyz="0.012 0.1928 -0.18038" rpy="0 0 0"/>
    <geometry>
      <mesh filename="package://robit_description/meshes/link_0_v1_1.stl" scale="0.001 0.001 0.001"/>
    </geometry>
  </collision>
</link>

<link name="link_1_v1_1">
  <inertial>
    <origin xyz="-0.039394228263145814 -1.6653345369377348e-16 0.04625624153739544" rpy="0 0 0"/>
    <mass value="21.785606731194406"/>
    <inertia ixx="0.254448" iyy="0.061359" izz="0.284201" ixy="-0.0" iyz="-0.0" ixz="0.002515"/>
  </inertial>
  <visual>
    <origin xyz="0.012 0.1928 -0.31238" rpy="0 0 0"/>
    <geometry>
      <mesh filename="package://robit_description/meshes/link_1_v1_1.stl" scale="0.001 0.001 0.001"/>
    </geometry>
    <material name="silver"/>
  </visual>
  <collision>
    <origin xyz="0.012 0.1928 -0.31238" rpy="0 0 0"/>
    <geometry>
      <mesh filename="package://robit_description/meshes/link_1_v1_1.stl" scale="0.001 0.001 0.001"/>
    </geometry>
  </collision>
</link>

<link name="link_2_v5_1">
  <inertial>
    <origin xyz="-0.25277949739829997 -0.06850000000000012 0.004067537852384506" rpy="0 0 0"/>
    <mass value="25.061881474743267"/>
    <inertia ixx="0.053179" iyy="0.344084" izz="0.378633" ixy="0.0" iyz="0.0" ixz="0.016978"/>
  </inertial>
  <visual>
    <origin xyz="0.012 0.1243 -0.346381" rpy="0 0 0"/>
    <geometry>
      <mesh filename="package://robit_description/meshes/link_2_v5_1.stl" scale="0.001 0.001 0.001"/>
    </geometry>
    <material name="silver"/>
  </visual>
  <collision>
    <origin xyz="0.012 0.1243 -0.346381" rpy="0 0 0"/>
    <geometry>
      <mesh filename="package://robit_description/meshes/link_2_v5_1.stl" scale="0.001 0.001 0.001"/>
    </geometry>
  </collision>
</link>

<link name="link_3_v3_1">
  <inertial>
    <origin xyz="0.20347863528799276 -0.06799999997155184 0.03213993670317289" rpy="0 0 0"/>
    <mass value="4.117252099821869"/>
    <inertia ixx="0.003331" iyy="0.044832" izz="0.046145" ixy="-0.0" iyz="0.0" ixz="0.001079"/>
  </inertial>
  <visual>
    <origin xyz="0.431168 0.1248 -0.381037" rpy="0 0 0"/>
    <geometry>
      <mesh filename="package://robit_description/meshes/link_3_v3_1.stl" scale="0.001 0.001 0.001"/>
    </geometry>
    <material name="silver"/>
  </visual>
  <collision>
    <origin xyz="0.431168 0.1248 -0.381037" rpy="0 0 0"/>
    <geometry>
      <mesh filename="package://robit_description/meshes/link_3_v3_1.stl" scale="0.001 0.001 0.001"/>
    </geometry>
  </collision>
</link>

<link name="link_4_v1_1">
  <inertial>
    <origin xyz="0.03631742506056769 2.979910762590521e-11 5.0489209091342246e-08" rpy="0 0 0"/>
    <mass value="1.0583786097940588"/>
    <inertia ixx="0.000338" iyy="0.000585" izz="0.000644" ixy="-0.0" iyz="0.0" ixz="-0.0"/>
  </inertial>
  <visual>
    <origin xyz="0.064384 0.1928 -0.418434" rpy="0 0 0"/>
    <geometry>
      <mesh filename="package://robit_description/meshes/link_4_v1_1.stl" scale="0.001 0.001 0.001"/>
    </geometry>
    <material name="silver"/>
  </visual>
  <collision>
    <origin xyz="0.064384 0.1928 -0.418434" rpy="0 0 0"/>
    <geometry>
      <mesh filename="package://robit_description/meshes/link_4_v1_1.stl" scale="0.001 0.001 0.001"/>
    </geometry>
  </collision>
</link>

<link name="link_5_v1_1">
  <inertial>
    <origin xyz="0.04370309439168263 -0.02599999997017921 0.07712670119676657" rpy="0 0 0"/>
    <mass value="3.317505240670039"/>
    <inertia ixx="0.010159" iyy="0.009789" izz="0.001388" ixy="0.0" iyz="0.0" ixz="-7.6e-05"/>
  </inertial>
  <visual>
    <origin xyz="0.007684 0.1668 -0.418434" rpy="0 0 0"/>
    <geometry>
      <mesh filename="package://robit_description/meshes/link_5_v1_1.stl" scale="0.001 0.001 0.001"/>
    </geometry>
    <material name="silver"/>
  </visual>
  <collision>
    <origin xyz="0.007684 0.1668 -0.418434" rpy="0 0 0"/>
    <geometry>
      <mesh filename="package://robit_description/meshes/link_5_v1_1.stl" scale="0.001 0.001 0.001"/>
    </geometry>
  </collision>
</link>

<link name="end_effector_v1_1">
  <inertial>
    <origin xyz="0.09492831983381403 2.9822616598451646e-11 5.048920731498541e-08" rpy="0 0 0"/>
    <mass value="9.548925481685224"/>
    <inertia ixx="0.011312" iyy="0.031229" izz="0.035821" ixy="0.0" iyz="-0.0" ixz="-0.0"/>
  </inertial>
  <visual>
    <origin xyz="-0.058316 0.1928 -0.418434" rpy="0 0 0"/>
    <geometry>
      <mesh filename="package://robit_description/meshes/end_effector_v1_1.stl" scale="0.001 0.001 0.001"/>
    </geometry>
    <material name="silver"/>
  </visual>
  <collision>
    <origin xyz="-0.058316 0.1928 -0.418434" rpy="0 0 0"/>
    <geometry>
      <mesh filename="package://robit_description/meshes/end_effector_v1_1.stl" scale="0.001 0.001 0.001"/>
    </geometry>
  </collision>
</link>

<joint name="Flipper 1" type="continuous">
  <origin xyz="0.0 0.0 0.112381" rpy="0 0 0"/>
  <parent link="base_link"/>
  <child link="flipper_v1__3__1"/>
  <axis xyz="0.0 1.0 0.0"/>
</joint>

<joint name="Flipper 2" type="continuous">
  <origin xyz="0.0 -0.3856 0.11238" rpy="0 0 0"/>
  <parent link="base_link"/>
  <child link="flipper_v1_1"/>
  <axis xyz="0.0 -1.0 -0.0"/>
</joint>

<joint name="Flipper 3" type="continuous">
  <origin xyz="-0.4953 0.0 0.112381" rpy="0 0 0"/>
  <parent link="base_link"/>
  <child link="flipper_v1__2__1"/>
  <axis xyz="0.0 1.0 0.0"/>
</joint>

<joint name="Flipper 4" type="continuous">
  <origin xyz="-0.4953 -0.3856 0.11238" rpy="0 0 0"/>
  <parent link="base_link"/>
  <child link="flipper_v1__1__1"/>
  <axis xyz="0.0 -1.0 -0.0"/>
</joint>

<joint name="Rigid" type="fixed">
  <origin xyz="-0.012 -0.1928 0.18038" rpy="0 0 0"/>
  <parent link="base_link"/>
  <child link="link_0_v1_1"/>
</joint>

<joint name="Joint 1" type="continuous">
  <origin xyz="0.0 0.0 0.132" rpy="0 0 0"/>
  <parent link="link_0_v1_1"/>
  <child link="link_1_v1_1"/>
  <axis xyz="0.0 -0.0 1.0"/>
</joint>

<joint name="Joint 2" type="continuous">
  <origin xyz="0.0 0.0685 0.034001" rpy="0 0 0"/>
  <parent link="link_1_v1_1"/>
  <child link="link_2_v5_1"/>
  <axis xyz="0.0 1.0 0.0"/>
</joint>

<joint name="Joint 3" type="continuous">
  <origin xyz="-0.419168 -0.0005 0.034656" rpy="0 0 0"/>
  <parent link="link_2_v5_1"/>
  <child link="link_3_v3_1"/>
  <axis xyz="0.0 1.0 0.0"/>
</joint>

<joint name="Joint 4" type="continuous">
  <origin xyz="0.366784 -0.068 0.037397" rpy="0 0 0"/>
  <parent link="link_3_v3_1"/>
  <child link="link_4_v1_1"/>
  <axis xyz="1.0 0.0 -0.0"/>
</joint>

<joint name="Joint 5" type="continuous">
  <origin xyz="0.0567 0.026 0.0" rpy="0 0 0"/>
  <parent link="link_4_v1_1"/>
  <child link="link_5_v1_1"/>
  <axis xyz="-0.0 1.0 0.0"/>
</joint>

<joint name="Joint 6" type="continuous">
  <origin xyz="0.066 -0.026 0.0" rpy="0 0 0"/>
  <parent link="link_5_v1_1"/>
  <child link="end_effector_v1_1"/>
  <axis xyz="1.0 0.0 -0.0"/>
</joint>

</robot>
